Workbook
Name Slicer_Product_Category: #N/A
Name Slicer_Warehouse_ID: #N/A

Sheet Cleaned_Data
A1: Order_ID | B1: Order_Date | C1: Delivery_Date | D1: Supplier_Name | E1: Product_Category | F1: Warehouse_ID | G1: Units_Ordered | H1: Units_Shipped | I1: Unit_Revenue | J1: COGS_Per_Unit | K1: Promised_Lead_Time | L1: Inventory_Value_OnHand | M1: Delivery_Days | N1: On_Time_Flag
A2: =RAW_DATA!A2 -> ORD-0001 | B2: 45052 | C2: 45053 | D2: GREENFIELD FOODS | E2: DAIRY | F2: =RAW_DATA!F2 -> WH-C | G2: =RAW_DATA!G2 -> 366 | H2: =RAW_DATA!H2 -> 366 | I2: =RAW_DATA!I2 -> 13.53 | J2: =RAW_DATA!J2 -> 9.04 | K2: =RAW_DATA!K2 -> 4 | L2: =RAW_DATA!L2 -> 3040.87 | M2: =C2-B2 -> 1 | N2: =IF(M2<=K2,"On Time", "Late") -> On Time
A3: =RAW_DATA!A3 -> ORD-0002 | B3: 45185 | C3: 45187 | D3: GREENFIELD FOODS | E3: BAKERY | F3: =RAW_DATA!F3 -> WH-B | G3: =RAW_DATA!G3 -> 386 | H3: =RAW_DATA!H3 -> 386 | I3: =RAW_DATA!I3 -> 9.02 | J3: =RAW_DATA!J3 -> 5.36 | K3: =RAW_DATA!K3 -> 4 | L3: =RAW_DATA!L3 -> 2593.56 | M3: =C3-B3 -> 2 | N3: =IF(M3<=K3,"On Time", "Late") -> On Time
A4: =RAW_DATA!A4 -> ORD-0003 | B4: 45101 | C4: 45102 | D4: NOVA COLD LOGISTICS | E4: BAKERY | F4: =RAW_DATA!F4 -> WH-D | G4: =RAW_DATA!G4 -> 192 | H4: =RAW_DATA!H4 -> 192 | I4: =RAW_DATA!I4 -> 8.22 | J4: =RAW_DATA!J4 -> 5.11 | K4: =RAW_DATA!K4 -> 3 | L4: =RAW_DATA!L4 -> 1085.49 | M4: =C4-B4 -> 1 | N4: =IF(M4<=K4,"On Time", "Late") -> On Time
A5: =RAW_DATA!A5 -> ORD-0004 | B5: 45201 | C5: 45203 | D5: PRIME REMOVAL LTD. | E5: DAIRY | F5: =RAW_DATA!F5 -> WH-D | G5: =RAW_DATA!G5 -> 60 | H5: =RAW_DATA!H5 -> 60 | I5: =RAW_DATA!I5 -> 15.57 | J5: =RAW_DATA!J5 -> 10.49 | K5: =RAW_DATA!K5 -> 3 | L5: =RAW_DATA!L5 -> 891.87 | M5: =C5-B5 -> 2 | N5: =IF(M5<=K5,"On Time", "Late") -> On Time
A6: =RAW_DATA!A6 -> ORD-0005 | B6: 45265 | C6: 45268 | D6: FRESH LINK PARTNERS | E6: DAIRY | F6: =RAW_DATA!F6 -> WH-A | G6: =RAW_DATA!G6 -> 60 | H6: =RAW_DATA!H6 -> 60 | I6: =RAW_DATA!I6 -> 15.84 | J6: =RAW_DATA!J6 -> 9.92 | K6: =RAW_DATA!K6 -> 5 | L6: =RAW_DATA!L6 -> 697.6 | M6: =C6-B6 -> 3 | N6: =IF(M6<=K6,"On Time", "Late") -> On Time
A7: =RAW_DATA!A7 -> ORD-0006 | B7: 45108 | C7: 45111 | D7: AGRIFLOW DISTRIBUTORS | E7: BAKERY | F7: =RAW_DATA!F7 -> WH-C | G7: =RAW_DATA!G7 -> 379 | H7: =RAW_DATA!H7 -> 379 | I7: =RAW_DATA!I7 -> $9.51 | J7: =RAW_DATA!J7 -> 6.39 | K7: =RAW_DATA!K7 -> 6 | L7: =RAW_DATA!L7 -> 2428.31 | M7: =C7-B7 -> 3 | N7: =IF(M7<=K7,"On Time", "Late") -> On Time
A8: =RAW_DATA!A8 -> ORD-0007 | B8: 45121 | C8: 45126 | D8: FRESH LINK PARTNERS | E8: BAKERY | F8: =RAW_DATA!F8 -> WH-D | G8: =RAW_DATA!G8 -> 132 | H8: =RAW_DATA!H8 -> 132 | I8: =RAW_DATA!I8 -> 10.45 | J8: =RAW_DATA!J8 -> 7.37 | K8: =RAW_DATA!K8 -> 5 | L8: =RAW_DATA!L8 -> 1009.25 | M8: =C8-B8 -> 5 | N8: =IF(M8<=K8,"On Time", "Late") -> On Time
A9: =RAW_DATA!A9 -> ORD-0008 | B9: 45064 | C9: 45067 | D9: NOVA COLD LOGISTICS | E9: BEVERAGES | F9: =RAW_DATA!F9 -> WH-D | G9: =RAW_DATA!G9 -> 387 | H9: =RAW_DATA!H9 -> 387 | I9: =RAW_DATA!I9 -> 17.9 | J9: =RAW_DATA!J9 -> 11.26 | K9: =RAW_DATA!K9 -> 3 | L9: =RAW_DATA!L9 -> 6313.01 | M9: =C9-B9 -> 3 | N9: =IF(M9<=K9,"On Time", "Late") -> On Time
A10: =RAW_DATA!A10 -> ORD-0009 | B10: 44998 | C10: 45003 | D10: BLUE STAR WHOLESALE | E10: BAKERY | F10: =RAW_DATA!F10 -> WH-C | G10: =RAW_DATA!G10 -> 295 | H10: =RAW_DATA!H10 -> 295 | I10: =RAW_DATA!I10 -> 9.21 | J10: =RAW_DATA!J10 -> 6.72 | K10: =RAW_DATA!K10 -> 7 | L10: =RAW_DATA!L10 -> 2259.22 | M10: =C10-B10 -> 5 | N10: =IF(M10<=K10,"On Time", "Late") -> On Time
A11: =RAW_DATA!A11 -> ORD-0010 | B11: 45179 | C11: 45180 | D11: FRESH LINK PARTNERS | E11: BAKERY | F11: =RAW_DATA!F11 -> WH-E | G11: =RAW_DATA!G11 -> 76 | H11: =RAW_DATA!H11 -> 76 | I11: =RAW_DATA!I11 -> 7.17 | J11: =RAW_DATA!J11 -> 4.92 | K11: =RAW_DATA!K11 -> 5 | L11: =RAW_DATA!L11 -> 470.33 | M11: =C11-B11 -> 1 | N11: =IF(M11<=K11,"On Time", "Late") -> On Time
A12: =RAW_DATA!A12 -> ORD-0011 | B12: 45166 | C12: 45167 | D12: SWIFT CHAIN INC | E12: FROZEN | F12: =RAW_DATA!F12 -> WH-E | G12: =RAW_DATA!G12 -> 368 | H12: =RAW_DATA!H12 -> 368 | I12: =RAW_DATA!I12 -> 24.18 | J12: =RAW_DATA!J12 -> 15.9 | K12: =RAW_DATA!K12 -> 4 | L12: =RAW_DATA!L12 -> 6202.83 | M12: =C12-B12 -> 1 | N12: =IF(M12<=K12,"On Time", "Late") -> On Time
A13: =RAW_DATA!A13 -> ORD-0012 | B13: 45149 | C13: 45150 | D13: AGRIFLOW DISTRIBUTORS | E13: DAIRY | F13: =RAW_DATA!F13 -> WH-C | G13: =RAW_DATA!G13 -> 389 | H13: =RAW_DATA!H13 -> 389 | I13: =RAW_DATA!I13 -> 11.5 | J13: =RAW_DATA!J13 -> 7.48 | K13: =RAW_DATA!K13 -> 6 | L13: =RAW_DATA!L13 -> 2930.64 | M13: =C13-B13 -> 1 | N13: =IF(M13<=K13,"On Time", "Late") -> On Time
... A36: =RAW_DATA!A36 -> ORD-0035 | B36: 45167 | C36: 45171 | D36: GREENFIELD FOODS | E36: FROZEN | F36: =RAW_DATA!F36 -> WH-A | G36: =RAW_DATA!G36 -> 199 | H36: =RAW_DATA!H36 -> 199 | I36: =RAW_DATA!I36 -> 25.54 | J36: =RAW_DATA!J36 -> 15.21 | K36: =RAW_DATA!K36 -> 4 | L36: =RAW_DATA!L36 -> 2767.09 | M36: =C36-B36 -> 4 | N36: =IF(M36<=K36,"On Time", "Late") -> On Time
A37: =RAW_DATA!A37 -> ORD-0036 | B37: 45112 | C37: 45077 | D37: FRESH LINK PARTNERS | E37: FROZEN | F37: =RAW_DATA!F37 -> WH-C | G37: =RAW_DATA!G37 -> 199 | H37: =RAW_DATA!H37 -> 199 | I37: =RAW_DATA!I37 -> 20.8 | J37: =RAW_DATA!J37 -> 15.52 | K37: =RAW_DATA!K37 -> 5 | L37: =RAW_DATA!L37 -> 3773.29 | M37: Data Error | N37: Not Applicable
A38: =RAW_DATA!A38 -> ORD-0037 | B38: 45119 | C38: 45020 | D38: NOVA COLD LOGISTICS | E38: DAIRY | F38: =RAW_DATA!F38 -> WH-C | G38: =RAW_DATA!G38 -> 39 | H38: =RAW_DATA!H38 -> 39 | I38: =RAW_DATA!I38 -> 12.73 | J38: =RAW_DATA!J38 -> 8.86 | K38: =RAW_DATA!K38 -> 3 | L38: =RAW_DATA!L38 -> 376.02 | M38: Data Error | N38: Not Applicable
A39: =RAW_DATA!A39 -> ORD-0038 | B39: 44995 | C39: 45028 | D39: GREENFIELD FOODS | E39: FROZEN | F39: =RAW_DATA!F39 -> WH-E | G39: =RAW_DATA!G39 -> 20 | H39: =RAW_DATA!H39 -> 20 | I39: =RAW_DATA!I39 -> 25.68 | J39: =RAW_DATA!J39 -> 17.65 | K39: =RAW_DATA!K39 -> 4 | L39: =RAW_DATA!L39 -> 516.85 | M39: =C39-B39 -> 33 | N39: =IF(M39<=K39,"On Time", "Late") -> Late
A40: =RAW_DATA!A40 -> ORD-0039 | B40: 45182 | C40: 44970 | D40: FRESH LINK PARTNERS | E40: BEVERAGES | F40: =RAW_DATA!F40 -> WH-D | G40: =RAW_DATA!G40 -> 339 | H40: =RAW_DATA!H40 -> 339 | I40: =RAW_DATA!I40 -> 19.63 | J40: =RAW_DATA!J40 -> 13.62 | K40: =RAW_DATA!K40 -> 5 | L40: =RAW_DATA!L40 -> 4987.45 | M40: Data Error | N40: Not Applicable
A41: =RAW_DATA!A41 -> ORD-0040 | B41: 44960 | C41: 45136 | D41: PRIME REMOVAL LTD. | E41: FROZEN | F41: =RAW_DATA!F41 -> WH-C | G41: =RAW_DATA!G41 -> 85 | H41: =RAW_DATA!H41 -> 85 | I41: =RAW_DATA!I41 -> 23.98 | J41: =RAW_DATA!J41 -> 15.01 | K41: =RAW_DATA!K41 -> 3 | L41: =RAW_DATA!L41 -> 1720.97 | M41: =C41-B41 -> 176 | N41: =IF(M41<=K41,"On Time", "Late") -> Late
A42: =RAW_DATA!A42 -> ORD-0041 | B42: 44950 | C42: 45082 | D42: RAPID SUPPLY CO | E42: PRODUCE | F42: =RAW_DATA!F42 -> WH-E | G42: =RAW_DATA!G42 -> 175 | H42: =RAW_DATA!H42 -> 175 | I42: =RAW_DATA!I42 -> 6.35 | J42: =RAW_DATA!J42 -> 4.23 | K42: =RAW_DATA!K42 -> 2 | L42: =RAW_DATA!L42 -> 957.01 | M42: =C42-B42 -> 132 | N42: =IF(M42<=K42,"On Time", "Late") -> Late
A43: =RAW_DATA!A43 -> ORD-0042 | B43: 45204 | C43: 45276 | D43: BLUE STAR WHOLESALE | E43: FROZEN | F43: =RAW_DATA!F43 -> WH-D | G43: =RAW_DATA!G43 -> 396 | H43: =RAW_DATA!H43 -> 396 | I43: =RAW_DATA!I43 -> 17.02 | J43: =RAW_DATA!J43 -> 11.12 | K43: =RAW_DATA!K43 -> 7 | L43: =RAW_DATA!L43 -> 5635.47 | M43: =C43-B43 -> 72 | N43: =IF(M43<=K43,"On Time", "Late") -> Late
A44: =RAW_DATA!A44 -> ORD-0043 | B44: 45279 | C44: 45273 | D44: AGRIFLOW DISTRIBUTORS | E44: DAIRY | F44: =RAW_DATA!F44 -> WH-B | G44: =RAW_DATA!G44 -> 95 | H44: =RAW_DATA!H44 -> 73 | I44: =RAW_DATA!I44 -> 16.68 | J44: =RAW_DATA!J44 -> 11.21 | K44: =RAW_DATA!K44 -> 6 | L44: =RAW_DATA!L44 -> 1449.5 | M44: Data Error | N44: Not Applicable
A45: =RAW_DATA!A45 -> ORD-0044 | B45: 45264 | C45: 45030 | D45: BLUE STAR WHOLESALE | E45: FROZEN | F45: =RAW_DATA!F45 -> WH-E | G45: =RAW_DATA!G45 -> 273 | H45: =RAW_DATA!H45 -> 273 | I45: =RAW_DATA!I45 -> 17.77 | J45: =RAW_DATA!J45 -> 12.22 | K45: =RAW_DATA!K45 -> 7 | L45: =RAW_DATA!L45 -> 0 | M45: Data Error | N45: Not Applicable
A46: =RAW_DATA!A46 -> ORD-0045 | B46: 45017 | C46: 45021 | D46: GREENFIELD FOODS | E46: FROZEN | F46: =RAW_DATA!F46 -> WH-B | G46: =RAW_DATA!G46 -> 45 | H46: =RAW_DATA!H46 -> 45 | I46: =RAW_DATA!I46 -> 27.01 | J46: =RAW_DATA!J46 -> 15.51 | K46: =RAW_DATA!K46 -> 4 | L46: =RAW_DATA!L46 -> 683.99 | M46: =C46-B46 -> 4 | N46: =IF(M46<=K46,"On Time", "Late") -> On Time
A47: =RAW_DATA!A47 -> ORD-0046 | B47: 45231 | C47: 45238 | D47: BLUE STAR WHOLESALE | E47: PRODUCE | F47: =RAW_DATA!F47 -> WH-E | G47: =RAW_DATA!G47 -> 246 | H47: =RAW_DATA!H47 -> 246 | I47: =RAW_DATA!I47 -> 7.39 | J47: =RAW_DATA!J47 -> 4.81 | K47: =RAW_DATA!K47 -> 7 | L47: =RAW_DATA!L47 -> 1654.6 | M47: =C47-B47 -> 7 | N47: =IF(M47<=K47,"On Time", "Late") -> On Time
A48: =RAW_DATA!A48 -> ORD-0047 | B48: 45157 | C48: 45159 | D48: BLUE STAR WHOLESALE | E48: BAKERY | F48: =RAW_DATA!F48 -> WH-D | G48: =RAW_DATA!G48 -> 9999 | H48: =RAW_DATA!H48 -> 9999 | I48: =RAW_DATA!I48 -> 10.13 | J48: =RAW_DATA!J48 -> 6.55 | K48: =RAW_DATA!K48 -> 7 | L48: =RAW_DATA!L48 -> 2364.99 | M48: =C48-B48 -> 2 | N48: =IF(M48<=K48,"On Time", "Late") -> On Time
A49: =RAW_DATA!A49 -> ORD-0048 | B49: 45047 | C49: 45050 | D49: BLUE STAR WHOLESALE | E49: DAIRY | F49: =RAW_DATA!F49 -> WH-C | G49: =RAW_DATA!G49 -> 296 | H49: =RAW_DATA!H49 -> 296 | I49: =RAW_DATA!I49 -> 10.69 | J49: =RAW_DATA!J49 -> 6.7 | K49: =RAW_DATA!K49 -> 7 | L49: =RAW_DATA!L49 -> 1966.71 | M49: =C49-B49 -> 3 | N49: =IF(M49<=K49,"On Time", "Late") -> On Time
A50: =RAW_DATA!A50 -> ORD-0049 | B50: 45135 | C50: 45139 | D50: FRESH LINK PARTNERS | E50: DAIRY | F50: =RAW_DATA!F50 -> WH-D | G50: =RAW_DATA!G50 -> 232 | H50: =RAW_DATA!H50 -> 232 | I50: =RAW_DATA!I50 -> 15.6 | J50: =RAW_DATA!J50 -> 9.8 | K50: =RAW_DATA!K50 -> 5 | L50: =RAW_DATA!L50 -> 3096.36 | M50: =C50-B50 -> 4 | N50: =IF(M50<=K50,"On Time", "Late") -> On Time
A51: =RAW_DATA!A51 -> ORD-0050 | B51: 45171 | C51: 45173 | D51: NOVA COLD LOGISTICS | E51: PRODUCE | F51: =RAW_DATA!F51 -> WH-D | G51: =RAW_DATA!G51 -> 172 | H51: =RAW_DATA!H51 -> 172 | I51: =RAW_DATA!I51 -> 7.87 | J51: =RAW_DATA!J51 -> 5.83 | K51: =RAW_DATA!K51 -> 3 | L51: =RAW_DATA!L51 -> 1154.59 | M51: =C51-B51 -> 2 | N51: =IF(M51<=K51,"On Time", "Late") -> On Time
A52: =RAW_DATA!A52 -> ORD-0051 | B52: 45066 | C52: 45067 | D52: FRESH LINK PARTNERS | E52: FROZEN | F52: =RAW_DATA!F52 -> WH-B | G52: =RAW_DATA!G52 -> 219 | H52: =RAW_DATA!H52 -> 219 | I52: =RAW_DATA!I52 -> 24.15 | J52: =RAW_DATA!J52 -> 15.24 | K52: =RAW_DATA!K52 -> 5 | L52: =RAW_DATA!L52 -> 3334.31 | M52: =C52-B52 -> 1 | N52: =IF(M52<=K52,"On Time", "Late") -> On Time
A53: =RAW_DATA!A53 -> ORD-0052 | B53: 45200 | C53: 45204 | D53: BLUE STAR WHOLESALE | E53: BAKERY | F53: =RAW_DATA!F53 -> WH-E | G53: =RAW_DATA!G53 -> 323 | H53: =RAW_DATA!H53 -> 323 | I53: =RAW_DATA!I53 -> 6.53 | J53: =RAW_DATA!J53 -> 4.43 | K53: =RAW_DATA!K53 -> 7 | L53: =RAW_DATA!L53 -> 1404.3 | M53: =C53-B53 -> 4 | N53: =IF(M53<=K53,"On Time", "Late") -> On Time
A54: =RAW_DATA!A54 -> ORD-0053 | B54: 45060 | C54: 45062 | D54: BLUE STAR WHOLESALE | E54: BAKERY | F54: =RAW_DATA!F54 -> WH-A | G54: =RAW_DATA!G54 -> 252 | H54: =RAW_DATA!H54 -> 252 | I54: =RAW_DATA!I54 -> 10.05 | J54: =RAW_DATA!J54 -> 6.29 | K54: =RAW_DATA!K54 -> 7 | L54: =RAW_DATA!L54 -> 2141.77 | M54: =C54-B54 -> 2 | N54: =IF(M54<=K54,"On Time", "Late") -> On Time
A55: =RAW_DATA!A55 -> ORD-0054 | B55: 45167 | C55: 45168 | D55: SWIFT CHAIN INC | E55: BEVERAGES | F55: =RAW_DATA!F55 -> WH-A | G55: =RAW_DATA!G55 -> 199 | H55: =RAW_DATA!H55 -> 199 | I55: =RAW_DATA!I55 -> 12.62 | J55: =RAW_DATA!J55 -> 9.36 | K55: =RAW_DATA!K55 -> 4 | L55: =RAW_DATA!L55 -> 1721.37 | M55: =C55-B55 -> 1 | N55: =IF(M55<=K55,"On Time", "Late") -> On Time
A56: =RAW_DATA!A56 -> ORD-0055 | B56: 44937 | C56: 44938 | D56: NOVA COLD LOGISTICS | E56: BAKERY | F56: =RAW_DATA!F56 -> WH-B | G56: =RAW_DATA!G56 -> 84 | H56: =RAW_DATA!H56 -> 84 | I56: =RAW_DATA!I56 -> 6.95 | J56: =RAW_DATA!J56 -> 5.14 | K56: =RAW_DATA!K56 -> 3 | L56: =RAW_DATA!L56 -> 509.05 | M56: =C56-B56 -> 1 | N56: =IF(M56<=K56,"On Time", "Late") -> On Time
A57: =RAW_DATA!A57 -> ORD-0056 | B57: 45237 | C57: 45240 | D57: PRIME REMOVAL LTD. | E57: BEVERAGES | F57: =RAW_DATA!F57 -> WH-B | G57: =RAW_DATA!G57 -> 387 | H57: =RAW_DATA!H57 -> 387 | I57: =RAW_DATA!I57 -> 19.37 | J57: =RAW_DATA!J57 -> 14.39 | K57: =RAW_DATA!K57 -> 3 | L57: =RAW_DATA!L57 -> 5373.23 | M57: =C57-B57 -> 3 | N57: =IF(M57<=K57,"On Time", "Late") -> On Time
... A70: =RAW_DATA!A70 -> ORD-0069 | B70: 45212 | C70: 45214 | D70: GREENFIELD FOODS | E70: BAKERY | F70: =RAW_DATA!F70 -> WH-A | G70: =RAW_DATA!G70 -> 287 | H70: =RAW_DATA!H70 -> 287 | I70: =RAW_DATA!I70 -> 10.76 | J70: =RAW_DATA!J70 -> 6.56 | K70: =RAW_DATA!K70 -> 4 | L70: =RAW_DATA!L70 -> 2359.26 | M70: =C70-B70 -> 2 | N70: =IF(M70<=K70,"On Time", "Late") -> On Time
A71: =RAW_DATA!A71 -> ORD-0070 | B71: 45244 | C71: 45242 | D71: SWIFT CHAIN INC | E71: BEVERAGES | F71: =RAW_DATA!F71 -> WH-E | G71: =RAW_DATA!G71 -> 126 | H71: =RAW_DATA!H71 -> 126 | I71: =RAW_DATA!I71 -> 14.38 | J71: =RAW_DATA!J71 -> 8.14 | K71: =RAW_DATA!K71 -> 4 | L71: =RAW_DATA!L71 -> 1070.69 | M71: Data Error | N71: Not Applicable
A72: =RAW_DATA!A72 -> ORD-0071 | B72: 45136 | C72: 45140 | D72: GREENFIELD FOODS | E72: BAKERY | F72: =RAW_DATA!F72 -> WH-A | G72: =RAW_DATA!G72 -> 169 | H72: =RAW_DATA!H72 -> 136 | I72: =RAW_DATA!I72 -> 9.79 | J72: =RAW_DATA!J72 -> 6.76 | K72: =RAW_DATA!K72 -> 4 | L72: =RAW_DATA!L72 -> 1339.42 | M72: =C72-B72 -> 4 | N72: =IF(M72<=K72,"On Time", "Late") -> On Time
A73: =RAW_DATA!A73 -> ORD-0072 | B73: 45265 | C73: 45267 | D73: FRESH LINK PARTNERS | E73: BEVERAGES | F73: =RAW_DATA!F73 -> WH-E | G73: =RAW_DATA!G73 -> 237 | H73: =RAW_DATA!H73 -> 237 | I73: =RAW_DATA!I73 -> 14.02 | J73: =RAW_DATA!J73 -> 8.13 | K73: =RAW_DATA!K73 -> 5 | L73: =RAW_DATA!L73 -> 2041.22 | M73: =C73-B73 -> 2 | N73: =IF(M73<=K73,"On Time", "Late") -> On Time
A74: =RAW_DATA!A74 -> ORD-0073 | B74: 45011 | C74: 45013 | D74: RAPID SUPPLY CO | E74: DAIRY | F74: =RAW_DATA!F74 -> WH-A | G74: =RAW_DATA!G74 -> 244 | H74: =RAW_DATA!H74 -> 244 | I74: =RAW_DATA!I74 -> 14.56 | J74: =RAW_DATA!J74 -> 10.05 | K74: =RAW_DATA!K74 -> 2 | L74: =RAW_DATA!L74 -> 3593.96 | M74: =C74-B74 -> 2 | N74: =IF(M74<=K74,"On Time", "Late") -> On Time
...

Sheet KPI_CALC
A1: References | B1: Formula | C1: Target | D1: Explanation
A2: On-Time Delivery Rate (OTD%) | B2: On time deliveries / total order * 100, Countif(On_time_flag, "On Time")/Count(Column A) | C2: 0.95 | D2: Percentage of orders reaching customers on time
A3: Order Fill Rate | B3: Total orders placed/ total orders shipped * 100, Sum (Units_Shipped / Sum (Units_Ordered) | C3: 0.98 | D3: Percentage of customer orders that were completed
A4: Inventory Turnover | B4: Total_COGS/ Average_Inventory_Value | C4: 8-12 times | D4: An efficiency metric that measures how many times a company's inventory is sold and replaced over a specific period
A5: Days of Stock (DOS) | B5: 365/Inventory_Turnover | C5: 30-45 days | D5: How many days of supply currently on hand
A9: On-Time Delivery Rate (OTD%) | B9: Order Fill Rate | C9: Inventory Turnover | D9: Days of Stock (DOS) [In days]
A10: =COUNTIF(Cleaned_Data!N2:N489, "On Time")/COUNTA(Cleaned_Data!A2:A489) -> 0.88729508 | B10: =SUM(Cleaned_Data!H2:H489)/SUM(Cleaned_Data!G2:G489) -> 0.99373516 | C10: =SUM(Cleaned_Data!J2:J489)/AVERAGE(Cleaned_Data!L2:L489) -> 2.0309161 | D10: =365/C10 -> 179.72185
A11: =IF(A10>=95%,"Target Reached","Needs Improvement") -> Needs Improvement | B11: =IF(B10>=98%, "Target Reached", "Below Target") -> Target Reached | C11: =IF(C10>=8,"Target Reached","Below Target") -> Below Target | D11: Above Target

Sheet PIVOT_TABLE_ANALYSIS
A3: Count of Order_ID | B3: Column Labels | K3: Row Labels | L3: Average of Unit_Revenue | M3: Average of COGS_Per_Unit
A4: Row Labels | B4: Late | C4: Not Applicable | D4: On Time | E4: Grand Total | K4: PRODUCE | L4: 6.6869388 | M4: 4.3732039
A5: AGRIFLOW DISTRIBUTORS | B5: 2 | C5: 1 | D5: 57 | E5: 60 | K5: FROZEN | L5: 22.106421 | M5: 14.321327
A6: BLUE STAR WHOLESALE | B6: 1 | C6: 2 | D6: 69 | E6: 72 | K6: DAIRY | L6: 13.273763 | M6: 8.5874227
A7: FRESH LINK PARTNERS | B7: 5 | C7: 3 | D7: 44 | E7: 52 | K7: BEVERAGES | L7: 17.107234 | M7: 11.385
A8: GREENFIELD FOODS | B8: 9 | D8: 51 | E8: 60 | K8: BAKERY | L8: 9.0376404 | M8: 5.9640426
A9: NOVA COLD LOGISTICS | B9: 15 | C9: 2 | D9: 37 | E9: 54 | K9: Grand Total | L9: 13.651002 | M9: 8.8944467
A10: PRIME REMOVAL LTD. | B10: 4 | C10: 1 | D10: 58 | E10: 63
A11: RAPID SUPPLY CO | B11: 2 | C11: 3 | D11: 63 | E11: 68
A12: SWIFT CHAIN INC | B12: 4 | C12: 1 | D12: 54 | E12: 59
A13: Grand Total | B13: 42 | C13: 13 | D13: 433 | E13: 488
A17: Sum of Units_Shipped | B17: Column Labels
A18: Row Labels | B18: PRODUCE | C18: BAKERY | D18: BEVERAGES | E18: DAIRY | F18: FROZEN | G18: Grand Total
A19: 0 | C19: 157 | E19: 345 | F19: 570 | G19: 1072
A20: WH-A | B20: 3352 | C20: 4695 | D20: 4634 | E20: 3929 | F20: 6110 | G20: 22720
A21: WH-B | B21: 4805 | C21: 4572 | D21: 3983 | E21: 4228 | F21: 3472 | G21: 21060
A22: WH-C | B22: 2970 | C22: 3619 | D22: 4204 | E22: 5927 | F22: 2593 | G22: 19313
A23: WH-D | B23: 3917 | C23: 13639 | D23: 3402 | E23: 3288 | F23: 3523 | G23: 27769
A24: WH-E | B24: 15060 | C24: 3296 | D24: 4292 | E24: 2394 | F24: 3576 | G24: 28618
A25: Grand Total | B25: 30104 | C25: 29978 | D25: 20515 | E25: 20111 | F25: 19844 | G25: 120552
A28: Count of Order_ID | B28: Column Labels
A29: Row Labels | B29: Late | C29: Not Applicable | D29: On Time | E29: Grand Total
A30: PRODUCE | B30: 8 | C30: 2 | D30: 93 | E30: 103
A31: FROZEN | B31: 11 | C31: 2 | D31: 85 | E31: 98
A32: DAIRY | B32: 7 | C32: 2 | D32: 88 | E32: 97
A33: BEVERAGES | B33: 8 | C33: 5 | D33: 83 | E33: 96
A34: BAKERY | B34: 8 | C34: 2 | D34: 84 | E34: 94
A35: Grand Total | B35: 42 | C35: 13 | D35: 433 | E35: 488

Sheet Dashboard
A1: FreshCart Supply Chain Performance Dashboard
A2: Analysis Period: January 2023 – December 2023 | Prepared by: Saffan Nagani
F8: On-Time Delivery Rate | I8: Order Fill Rate
F9: =KPI_CALC!A10 -> 0.88729508 | I9: =KPI_CALC!B10 -> 0.99373516
F10: =KPI_CALC!A11 -> Needs Improvement | I10: =KPI_CALC!B11 -> Target Reached
F14: Inventory Turnover | I14: Days of Stock
F15: =KPI_CALC!C10 -> 2.0309161 | I15: =KPI_CALC!D10 -> 179.72185
F16: =KPI_CALC!C11 -> Below Target | I16: =KPI_CALC!D11 -> Above Target

Sheet RAW_DATA
A1: Order_ID | B1: Order_Date | C1: Delivery_Date | D1: Supplier_Name | E1: Product_Category | F1: Warehouse_ID | G1: Units_Ordered | H1: Units_Shipped | I1: Unit_Revenue | J1: COGS_Per_Unit | K1: Promised_Lead_Time | L1: Inventory_Value_OnHand
A2: ORD-0001 | B2: 45052 | C2: 45053 | D2: Greenfield Foods | E2: Dairy | F2: WH-C | G2: 366 | H2: 366 | I2: 13.53 | J2: 9.04 | K2: 4 | L2: 3040.87
A3: ORD-0002 | B3: 45185 | C3: 45187 | D3: Greenfield Foods | E3: Bakery | F3: WH-B | G3: 386 | H3: 386 | I3: 9.02 | J3: 5.36 | K3: 4 | L3: 2593.56
A4: ORD-0003 | B4: 45101 | C4: 45102 | D4: Nova Cold Logistics | E4: Bakery | F4: WH-D | G4: 192 | H4: 192 | I4: 8.22 | J4: 5.11 | K4: 3 | L4: 1085.49
A5: ORD-0004 | B5: 45201 | C5: 45203 | D5: Prime Mover Ltd | E5: Dairy | F5: WH-D | G5: 60 | H5: 60 | I5: 15.57 | J5: 10.49 | K5: 3 | L5: 891.87
A6: ORD-0005 | B6: 45265 | C6: 45268 | D6: FreshLink Partners | E6: Dairy | F6: WH-A | G6: 60 | H6: 60 | I6: 15.84 | J6: 9.92 | K6: 5 | L6: 697.6
A7: ORD-0006 | B7: 45108 | C7: 45111 | D7: AgriFlow Distributors | E7: Bakery | F7: WH-C | G7: 379 | H7: 379 | I7: $9.51 | J7: 6.39 | K7: 6 | L7: 2428.31
A8: ORD-0007 | B8: 45121 | C8: 45126 | D8: FreshLink Partners | E8: Bakery | F8: WH-D | G8: 132 | H8: 132 | I8: 10.45 | J8: 7.37 | K8: 5 | L8: 1009.25
A9: ORD-0008 | B9: 45064 | C9: 45067 | D9: NovaCold Logistics | E9: Beverages | F9: WH-D | G9: 387 | H9: 387 | I9: 17.9 | J9: 11.26 | K9: 3 | L9: 6313.01
A10: ORD-0009 | B10: 44998 | C10: 45003 | D10: BlueStar Wholesale | E10: Bakery | F10: WH-C | G10: 295 | H10: 295 | I10: 9.21 | J10: 6.72 | K10: 7 | L10: 2259.22
A11: ORD-0010 | B11: 45179 | C11: 45180 | D11: FreshLink Partners | E11: Bakery | F11: WH-E | G11: 76 | H11: 76 | I11: 7.17 | J11: 4.92 | K11: 5 | L11: 470.33
A12: ORD-0011 | B12: 45166 | C12: 45167 | D12: SwiftChain Inc | E12: Frozen | F12: WH-E | G12: 368 | H12: 368 | I12: 24.18 | J12: 15.9 | K12: 4 | L12: 6202.83
A13: ORD-0012 | B13: 45149 | C13: 45150 | D13: AgriFlow Distributors | E13: Dairy | F13: WH-C | G13: 389 | H13: 389 | I13: 11.5 | J13: 7.48 | K13: 6 | L13: 2930.64
A14: ORD-0013 | B14: 45238 | C14: 45241 | D14: Greenfield Foods | E14: Beverages | F14: WH-E | G14: 102 | H14: 102 | I14: 19.01 | J14: 12.47 | K14: 4 | L14: 1145.18
A15: ORD-0014 | B15: 44984 | C15: 44987 | D15: AgriFlow Distributors | E15: Frozen | F15: WH-A | G15: 142 | H15: 142 | I15: 26.54 | J15: 19.62 | K15: 6 | L15: 2650.62
A16: ORD-0015 | B16: 44991 | C16: 44995 | D16: BlueStar Wholesale | E16: Dairy | F16: WH-E | G16: 301 | H16: 301 | I16: 13.4 | J16: 9 | K16: 7 | L16: 4005.58
A17: ORD-0016 | B17: 45270 | C17: 45274 | D17: FreshLink Partners | E17: Beverages | F17: WH-D | G17: 284 | H17: 284 | I17: 14.23 | J17: 8.01 | K17: 5 | L17: 2076.07
A18: ORD-0017 | B18: 44930 | C18: 44931 | D18: FreshLink Partners | E18: Produce | F18: WH-B | G18: 137 | H18: 137 | I18: 4.91 | J18: 3.02 | K18: 5 | L18: 500
A19: ORD-0018 | B19: 45203 | C19: 45206 | D19: PrimeMover Ltd | E19: Frozen | F19: WH-B | G19: 315 | H19: 315 | I19: 25.42 | J19: 18.09 | K19: 3 | L19: 5779.53
... A23: ORD-0022 | B23: 45126 | C23: 45128 | D23: Rapid Supply Co | E23: Frozen | F23: WH-A | G23: 166 | H23: 166 | I23: 27.49 | J23: 20.59 | K23: 2 | L23: 4215.9
A24: ORD-0023 | B24: 45078 | C24: 45079 | D24: BlueStar Wholesale | E24: Bakery | F24: WH-B | G24: 316 | H24: 316 | I24: 6.69 | J24: 4.1 | K24: 7
A25: ORD-0024 | B25: 45007 | C25: 45012 | D25: BlueStar Wholesale | E25: Produce | F25: WH-E | G25: 61 | H25: 61 | I25: $5.05 | J25: 2.85 | K25: 7 | L25: 246.36
A26: ORD-0025 | B26: 45053 | C26: 45054 | D26: SwiftChain Inc | E26: Dairy | F26: WH-E | G26: 337 | H26: 337 | I26: 14.33 | J26: 9.5 | K26: 4 | L26: 3489.06
A27: ORD-0026 | B27: 45049 | C27: 45050 | D27: primemover ltd | E27: Bakery | F27: WH-C | G27: 363 | H27: 363 | I27: 8.59 | J27: 6.32 | K27: 3 | L27: 3352.78
A28: ORD-0027 | B28: 45215 | C28: 45219 | D28: Nova Cold Logistics | E28: Frozen | F28: WH-E | G28: 295 | H28: 295 | I28: 19.18 | J28: 14.13 | K28: 3 | L28: 5954.57
A29: ORD-0028 | B29: 45007 | C29: 45012 | D29: FreshLink Partners | E29: Beverages | F29: WH-C | G29: 380 | H29: 380 | I29: 20.85 | J29: 14.83 | K29: 5 | L29: 6860.34
A30: ORD-0029 | B30: 45062 | C30: 45063 | D30: primemover ltd | E30: Dairy | F30: WH-B | G30: 400 | H30: 400 | I30: 11.56 | J30: 7.76 | K30: 3 | L30: 4130.08
A31: ORD-0030 | B31: 45177 | C31: 45178 | D31: FreshLink Partners | E31: Beverages | F31: WH-E | G31: 67 | H31: 67 | I31: 19.46 | J31: 10.87 | K31: 5 | L31: 801.22
A32: ORD-0031 | B32: 45153 | C32: 45155 | D32: Rapid Supply Co | E32: Beverages | F32: WH-B | G32: 307 | H32: 223 | I32: 20.51 | J32: 14.12 | K32: 2 | L32: 4289.03
A33: ORD-0032 | B33: 45209 | C33: 45210 | D33: NovaCold Logistics | E33: Beverages | F33: WH-E | G33: 41 | H33: 41 | I33: 20.09 | J33: 14.25 | K33: 3 | L33: 827.54
A34: ORD-0033 | B34: 45268 | C34: 45273 | D34: AgriFlow Distributors | E34: Bakery | F34: WH-B | G34: 228 | H34: 228 | I34: 10 | J34: 7.35 | K34: 6 | L34: 1746.25
A35: ORD-0034 | B35: 44939 | C35: 44941 | D35: Rapid Supply Co | E35: Bakery | F35: WH-D | G35: 230 | H35: 230 | I35: 10.55 | J35: 7.51 | K35: 2 | L35: 1831.08
A36: ORD-0035 | B36: 08/29/2023 | C36: 45171 | D36: Greenfield Foods | E36: Frozen | F36: WH-A | G36: 199 | H36: 199 | I36: 25.54 | J36: 15.21 | K36: 4 | L36: 2767.09
A37: ORD-0036 | B37: 45069 | C37: 45077 | D37: FreshLink Partners | E37: Frozen | F37: WH-C | G37: 199 | H37: 199 | I37: 20.8 | J37: 15.52 | K37: 5 | L37: 3773.29
A38: ORD-0037 | B38: 45018 | C38: 45020 | D38: NovaCold Logistics | E38: Dairy | F38: WH-C | G38: 39 | H38: 39 | I38: 12.73 | J38: 8.86 | K38: 3 | L38: 376.02
A39: ORD-0038 | B39: 45024 | C39: 45028 | D39: Greenfield Foods | E39: Frozen | F39: WH-E | G39: 20 | H39: 20 | I39: 25.68 | J39: 17.65 | K39: 4 | L39: 516.85
A40: ORD-0039 | B40: 44962 | C40: 44970 | D40: FreshLink Partners | E40: Beverages | F40: WH-D | G40: 339 | H40: 339 | I40: 19.63 | J40: 13.62 | K40: 5 | L40: 4987.45
A41: ORD-0040 | B41: 45133 | C41: 45136 | D41: PrimeMover Ltd | E41: Frozen | F41: WH-C | G41: 85 | H41: 85 | I41: 23.98 | J41: 15.01 | K41: 3 | L41: 1720.97
A42: ORD-0041 | B42: 45081 | C42: 45082 | D42: Rapid supply co | E42: Produce | F42: WH-E | G42: 175 | H42: 175 | I42: 6.35 | J42: 4.23 | K42: 2 | L42: 957.01
A43: ORD-0042 | B43: 45272 | C43: 45276 | D43: BlueStar Wholesale | E43: Frozen | F43: WH-D | G43: 396 | H43: 396 | I43: 17.02 | J43: 11.12 | K43: 7 | L43: 5635.47
...
